Workbook

Sheet AMC Matrix
B3: Weightage for AMC Ranking
B4: Category | C4: Weightage
B5: Market Position & Scale | C5: =SUM(C6:C7)
B6: AUM | C6: 0.15
B7: No. of Schemes | C7: 0.1
B8: Performance Metrics | C8: =SUM(C9:C11)
B9: 3-Year Return | C9: 0.15
B10: 5-Year Return | C10: 0.1
B11: 10 Year Return | C11: 0.075
B12: Risk-Adjusted Returns | C12: =SUM(C13:C15)
B13: Sharpe | C13: 0.05
B14: Sortino | C14: 0.075
B15: Alpha | C15: 0.1
B16: Fund Management & Expense Efficiency | C16: =C17
B17: Expense Ratio | C17: 0.2
B18: Total Weightage | C18: =SUM(C5,C8,C12,C16)

Sheet Consol_Thematic (2)
A1: Funds | B1: 1 Yr Ret (%) | C1: Expense Ratio (%) | D1: 3 Yr Ret (%) | E1: 5 Yr Ret (%) | F1: Expense Ratio (%) | G1: Standard Deviation | H1: Sharpe Ratio | I1: Sortino Ratio | J1: Beta | K1: Alpha | L1: Category
A2: 360 ONE FlexiCap Fund - Regular Plan | B2: 4.23 | C2: 2.03 | D2: -- | E2: -- | F2: 2.03 | G2: -- | H2: -- | I2: -- | J2: -- | K2: -- | L2: EQ-FLX
A3: 360 ONE Focused Equity Fund - Regular Plan | B3: 1.94 | C3: 1.8 | D3: 20.36 | E3: 24.2 | F3: 1.8 | G3: 13.28 | H3: 0.94 | I3: 1.58 | J3: 0.88 | K3: 2.4 | L3: EQ-FLX
A4: 360 ONE Quant Fund - Regular Plan | B4: 6.46 | C4: 1.95 | D4: 28.72 | E4: -- | F4: 1.95 | G4: 18.03 | H4: 1.07 | I4: 1.6 | J4: 1.19 | K4: 5.59 | L4: EQ-THEMATIC
A5: Aditya Birla Sun Life Asset Allocator FoF - Regular Plan | B5: 9.61 | C5: 1.27 | D5: 17.35 | E5: 18.19 | F5: 1.27 | G5: 8.45 | H5: 1.12 | I5: 1.9 | J5: 0.84 | K5: 1.96 | L5: HY-MAA
A6: Aditya Birla Sun Life Balanced Advantage Fund - Regular Plan | B6: 9.56 | C6: 1.79 | D6: 14.63 | E6: 15.62 | F6: 1.79 | G6: 7.75 | H6: 0.91 | I6: 1.39 | J6: 0.74 | K6: 1.17 | L6: HY-DAA
A7: Aditya Birla Sun Life Bal Bhavishya Yojna - Regular Plan | B7: 4.02 | C7: 2.16 | D7: 16.53 | E7: 15.7 | F7: 2.16 | G7: 13.97 | H7: 0.65 | I7: 0.98 | J7: 0.94 | K7: -1.75 | L7: EQ-FLX
A8: Aditya Birla Sun Life BSE Sensex ETF | B8: 7.71 | C8: 0.04 | D8: 15.85 | E8: 20.64 | F8: 0.04 | G8: 12.69 | H8: 0.66 | I8: 1.1 | J8: 0.91 | K8: -0.96 | L8: EQ-LC
A9: Aditya Birla Sun Life Business Cycle Fund - Regular Plan | B9: 6.65 | C9: 2.14 | D9: 17.85 | E9: -- | F9: 2.14 | G9: 14.21 | H9: 0.68 | I9: 1.09 | J9: 0.96 | K9: -1.45 | L9: EQ-THEMATIC
A10: Aditya Birla Sun Life Conglomerate - Regular Plan | B10: -- | C10: 2.07 | D10: -- | E10: -- | F10: 2.07 | G10: -- | H10: -- | I10: -- | J10: -- | K10: -- | L10: EQ-THEMATIC
A11: Aditya Birla Sun Life Dividend Yield Fund - Regular Plan | B11: 1.84 | C11: 2.22 | D11: 23.93 | E11: 26.23 | F11: 2.22 | G11: 15.2 | H11: 1 | I11: 1.56 | J11: 0.97 | K11: 4.06 | L11: EQ-DIV Y
A12: Aditya Birla Sun Life Equity Advantage Fund - Regular Plan | B12: 4.58 | C12: 1.9 | D12: 17.54 | E12: 20.91 | F12: 1.9 | G12: 15.21 | H12: 0.62 | I12: 0.86 | J12: 1.01 | K12: -1.71 | L12: EQ-L&MC
A13: Aditya Birla Sun Life ESG Integration Strategy Fund - Regular Plan | B13: 9.7 | C13: 2.44 | D13: 17.21 | E13: -- | F13: 2.44 | G13: 14.57 | H13: 0.62 | I13: 0.98 | J13: 0.98 | K13: -1 | L13: EQ-T-ESG
A14: Aditya Birla Sun Life Financial Planning FoF - Aggressive Plan - Regular Plan | B14: 7.96 | C14: 1.13 | D14: 18.57 | E14: 19.56 | F14: 1.13 | G14: 10.49 | H14: 1 | I14: 1.44 | J14: 1.07 | K14: 1.02 | L14: HY-MAA
A15: Aditya Birla Sun Life Financial Planning FoF - Conservative Plan - Regular Plan | B15: 8.83 | C15: 0.94 | D15: 12.79 | E15: 12.42 | F15: 0.94 | G15: 4.72 | H15: 1.21 | I15: 1.84 | J15: 0.47 | K15: 1.49 | L15: HY-MAA
A16: Aditya Birla Sun Life Financial Planning FoF - Moderate Plan - Regular Plan | B16: 8.83 | C16: 1.09 | D16: 15.69 | E16: 16.02 | F16: 1.09 | G16: 7.64 | H16: 1.06 | I16: 1.54 | J16: 0.77 | K16: 1.24 | L16: HY-MAA
A17: Aditya Birla Sun Life Flexi Cap Fund - Regular Plan | B17: 9.73 | C17: 1.67 | D17: 20.22 | E17: 23.12 | F17: 1.67 | G17: 13.82 | H17: 0.87 | I17: 1.43 | J17: 0.94 | K17: 1.15 | L17: EQ-FLX
A18: Aditya Birla Sun Life Focused Fund - Regular Plan | B18: 9.28 | C18: 1.81 | D18: 18.92 | E18: 21.84 | F18: 1.81 | G18: 13.24 | H18: 0.8 | I18: 1.57 | J18: 0.9 | K18: 0.3 | L18: EQ-FLX
A19: Aditya Birla Sun Life Frontline Equity Fund - Regular Plan | B19: 7.48 | C19: 1.64 | D19: 18.54 | E19: 22.33 | F19: 1.64 | G19: 13.13 | H19: 0.81 | I19: 1.3 | J19: 0.95 | K19: 0.83 | L19: EQ-LC
A20: Aditya Birla Sun Life India GenNext Fund - Regular Plan | B20: 4.63 | C20: 1.85 | D20: 18.95 | E20: 22.13 | F20: 1.85 | G20: 14.6 | H20: 0.75 | I20: 1.16 | J20: 0.79 | K20: -0.37 | L20: EQ-Consumption
A21: Aditya Birla Sun Life Manufacturing Equity Fund - Regular Plan | B21: 2.01 | C21: 2.29 | D21: 20.58 | E21: 21.32 | F21: 2.29 | G21: 16.43 | H21: 0.8 | I21: 1.25 | J21: 1.07 | K21: 0.88 | L21: EQ-THEMATIC
A22: Aditya Birla Sun Life Mid Cap Fund - Regular Plan | B22: 6.66 | C22: 1.89 | D22: 22.4 | E22: 28.63 | F22: 1.89 | G22: 16.24 | H22: 0.85 | I22: 1.39 | J22: 0.92 | K22: -2.87 | L22: EQ-MC
A23: Aditya Birla Sun Life MNC Fund - Regular Plan | B23: -0.79 | C23: 2.01 | D23: 14.75 | E23: 13.98 | F23: 2.01 | G23: 14.9 | H23: 0.52 | I23: 0.89 | J23: 0.9 | K23: -2.66 | L23: EQ-MNC
A24: Aditya Birla Sun Life Multi Asset Allocation Fund - Regular Plan | B24: 10.57 | C24: 1.83 | D24: -- | E24: -- | F24: 1.83 | G24: -- | H24: -- | I24: -- | J24: -- | K24: -- | L24: HY-MAA
A25: Aditya Birla Sun Life Multi-Cap Fund - Regular Plan | B25: 4.72 | C25: 1.84 | D25: 19.48 | E25: -- | F25: 1.84 | G25: 14.3 | H25: 0.8 | I25: 1.06 | J25: 0.88 | K25: -1.43 | L25: EQ-MLC
A26: Aditya Birla Sun Life Multi - Index FoF - Regular Plan | B26: 6.41 | C26: 0.61 | D26: -- | E26: -- | F26: 0.61 | G26: -- | H26: -- | I26: -- | J26: -- | K26: -- | L26: HY-MAA
A27: Aditya Birla Sun Life Nifty 200 Momentum 30 ETF | B27: -11.83 | C27: 0.29 | D27: -- | E27: -- | F27: 0.29 | G27: -- | H27: -- | I27: -- | J27: -- | K27: -- | L27: EQ-L&MC
A28: Aditya Birla Sun Life Nifty 200 Quality 30 ETF | B28: 2.39 | C28: 0.29 | D28: -- | E28: -- | F28: 0.29 | G28: -- | H28: -- | I28: -- | J28: -- | K28: -- | L28: EQ-L&MC
A29: Aditya Birla Sun Life Nifty 50 Equal Weight Index Fund - Regular Plan | B29: 4.87 | C29: 1.02 | D29: 19.35 | E29: -- | F29: 1.02 | G29: 14.76 | H29: 0.77 | I29: 1.17 | J29: 1.04 | K29: 0.57 | L29: EQ-LC
A30: Aditya Birla Sun Life Nifty 50 ETF | B30: 7.81 | C30: 0.04 | D30: 16.6 | E30: 21.4 | F30: 0.04 | G30: 13.14 | H30: 0.69 | I30: 1.18 | J30: 0.95 | K30: -0.72 | L30: EQ-LC
A31: Aditya Birla Sun Life Nifty 50 Index Fund - Regular Plan | B31: 7.33 | C31: 0.47 | D31: 15.98 | E31: 20.62 | F31: 0.47 | G31: 13.12 | H31: 0.65 | I31: 1.11 | J31: 0.95 | K31: -1.25 | L31: EQ-LC
A32: Aditya Birla Sun Life Nifty India Defence Index Fund - Regular Plan | B32: -- | C32: 1.06 | D32: -- | E32: -- | F32: 1.06 | G32: -- | H32: -- | I32: -- | J32: -- | K32: -- | L32: EQ-THEMATIC
A33: Aditya Birla Sun Life Nifty Midcap 150 Index Fund - Regular Plan | B33: 5.32 | C33: 1.01 | D33: 27.02 | E33: -- | F33: 1.01 | G33: 17.01 | H33: 1.06 | I33: 1.53 | J33: 1 | K33: -0.09 | L33: EQ-MC
A34: Aditya Birla Sun Life Nifty Next 50 ETF | B34: -3.18 | C34: 0.09 | D34: 22.13 | E34: 22.68 | F34: 0.09 | G34: 19.54 | H34: 0.73 | I34: 1.09 | J34: 1.3 | K34: 0.85 | L34: EQ-LC
A35: Aditya Birla Sun Life Nifty Next 50 Index Fund - Regular Plan | B35: -4.32 | C35: 0.88 | D35: 20.8 | E35: -- | F35: 0.88 | G35: 19.52 | H35: 0.67 | I35: 1 | J35: 1.3 | K35: -0.25 | L35: EQ-LC
A36: Aditya Birla Sun Life Nifty PSE ETF | B36: -4.83 | C36: 0.2 | D36: -- | E36: -- | F36: 0.2 | G36: -- | H36: -- | I36: -- | J36: -- | K36: -- | L36: EQ-PSU
A37: Aditya Birla Sun Life Nifty Smallcap 50 Index Fund - Regular Plan | B37: 6.38 | C37: 1.01 | D37: 28.75 | E37: -- | F37: 1.01 | G37: 20.71 | H37: 0.92 | I37: 1.48 | J37: 1.03 | K37: 0.22 | L37: EQ-SC
A38: Aditya Birla Sun Life PSU Equity Fund - Regular Plan | B38: -5.53 | C38: 1.79 | D38: 32.4 | E38: 32.39 | F38: 1.79 | G38: 22.36 | H38: 1.07 | I38: 1.95 | J38: 0.97 | K38: -2.99 | L38: EQ-PSU
A39: Aditya Birla Sun Life Quant Fund - Regular Plan | B39: -- | C39: 1.97 | D39: -- | E39: -- | F39: 1.97 | G39: -- | H39: -- | I39: -- | J39: -- | K39: -- | L39: EQ-THEMATIC
A40: Aditya Birla Sun Life Retirement Fund - The 30s Plan - Regular Plan | B40: 8.28 | C40: 2.41 | D40: 17.78 | E40: 16.73 | F40: 2.41 | G40: 14.35 | H40: 0.69 | I40: 1.1 | J40: 0.94 | K40: -0.98 | L40: EQ-FLX
...

Sheet Table 1
A2: Financial Product Catalog: A Ready Reckoner , As on 04th September 2026
A4: Whats new? (August 2026) | E4: Debt
A5: Fund Name | B5: End Date
A6: Bank Of India Value Fund | B6: Sept 11, 2026 | E6: Debt Mutual Funds (Ultra Short Duration) | F6: 3-Year Return | G6: 1-Year Return
A7: ICICI Prudential Dynamic Asset Allocation Passive Fund of Fund | B7: Sept 09, 2026 | E7: NIFTY Ultra Short Duration Debt Index | F7: 0.0755 | G7: 0.0699
A8: Motilal Oswal Quality Fund | B8: Sept 11, 2026 | E8: Ultra Short - Fund Name ( Return CAGR ) | F8: 3-Year Return | G8: 1-Year Return
A9: UTI BSE India Sector Leaders Index Fund | B9: Sep 11, 2026 | E9: ='Summary '!J4 | F9: ='Summary '!K4 | G9: ='Summary '!L4
A10: Equity | E10: ='Summary '!J5 | F10: ='Summary '!K5 | G10: ='Summary '!L5
A11: Large Cap - Funds | B11: 3-Year Return | C11: 1-Year Return | E11: ='Summary '!J6 | F11: ='Summary '!K6 | G11: ='Summary '!L6
A12: NIFTY 50 | B12: 0.0835 | C12: -0.0235
A13: Large Cap - Funds (Return CAGR) | B13: 3-Year Return | C13: 1-Year Return | E13: Debt Mutual Funds (Low Duration) | F13: 3-Year Return | G13: 1-Year Return
A14: ='Summary '!D4 | B14: ='Summary '!E4 | C14: ='Summary '!F4 | E14: NIFTY Low Duration Debt Index | F14: 0.0725 | G14: 0.0637
A15: ='Summary '!D5 | B15: ='Summary '!E5 | C15: ='Summary '!F5 | E15: Low Duration - Funds ( Return CAGR ) | F15: 3-Year Return | G15: 1-Year Return
A16: ='Summary '!D6 | B16: ='Summary '!E6 | C16: ='Summary '!F6 | E16: ='Summary '!J8 | F16: ='Summary '!K8 | G16: ='Summary '!L8
A17: SIP of 50000*36=1800000, Maturity Value Would be | B17: 2572605 | E17: ='Summary '!J9 | F17: ='Summary '!K9 | G17: ='Summary '!L9
E18: ='Summary '!J10 | F18: ='Summary '!K10 | G18: ='Summary '!L10
A19: Large & Mid Cap - Funds | B19: 3-Year Return | C19: 1-Year Return
A20: ='Summary '!D8 | B20: ='Summary '!E8 | C20: ='Summary '!F8 | E20: Debt Mutual Funds (Short Duration) | F20: 3-Year Return | G20: 1-Year Return
A21: ='Summary '!D9 | B21: ='Summary '!E9 | C21: ='Summary '!F9 | E21: NIFTY Short Duration Debt Index A-II | F21: 0.0686 | G21: 0.0501
A22: ='Summary '!D10 | B22: ='Summary '!E10 | C22: ='Summary '!F10 | E22: Medium Term - Funds ( Return CAGR ) | F22: 3-Year Return | G22: 1-Year Return
A23: SIP of 50000*36=1800000, Maturity Value Would be | B23: 2646895 | E23: ='Summary '!J12 | F23: ='Summary '!K12 | G23: ='Summary '!L12
E24: ='Summary '!J13 | F24: ='Summary '!K13 | G24: ='Summary '!L13
A25: Mid Cap - Funds | B25: 3-Year Return | C25: 1-Year Return | E25: ='Summary '!J14 | F25: ='Summary '!K14 | G25: ='Summary '!L14
A26: NIFTY Midcap 100 | B26: 0.177 | C26: 0.1093
A27: Mid Cap - Funds (Return CAGR) | B27: 3-Year CAGR | C27: 1-Year Return | E27: Debt Mutual Funds (Medium Duration) | F27: 3-Year Return | G27: 1-Year Return
A28: ='Summary '!D12 | B28: ='Summary '!E12 | C28: ='Summary '!F12 | E28: NIFTY Medium Duration Debt Index A-III | F28: 0.0643 | G28: 0.0374
A29: ='Summary '!D13 | B29: ='Summary '!E13 | C29: ='Summary '!F13 | E29: Medium Term - Funds ( Return CAGR ) | F29: 3-Year Return | G29: 1-Year Return
A30: ='Summary '!D14 | B30: ='Summary '!E14 | C30: ='Summary '!F14 | E30: ='Summary '!J16 | F30: ='Summary '!K16 | G30: ='Summary '!L16
A31: SIP of 50000*36=1800000 , Maturity Value Would be | B31: 2767450 | E31: ='Summary '!J17 | F31: ='Summary '!K17 | G31: ='Summary '!L17
E32: ='Summary '!J18 | F32: ='Summary '!K18 | G32: ='Summary '!L18
A33: Small Cap - Funds | B33: 3-Year Return | C33: 1-Year Return
A34: NIFTY Smallcap 100 | B34: 0.1822 | C34: 0.1365 | E34: Debt Mutual Funds (Medium to Long Duration) | F34: 3-Year Return | G34: 1-Year Return
A35: Small Cap - Funds ( Return CAGR ) | B35: 3-Yr CAGR | C35: 1-Yr Return | E35: NIFTY Medium to Long Duration Debt Index | F35: 0.0547 | G35: 0.0125
A36: ='Summary '!D16 | B36: ='Summary '!E16 | C36: ='Summary '!F16 | E36: Medium to Long Term - Funds ( Return CAGR ) | F36: 3-Year Return | G36: 1-Year Return
A37: ='Summary '!D17 | B37: ='Summary '!E17 | C37: ='Summary '!F17 | E37: ='Summary '!J20 | F37: ='Summary '!K20 | G37: ='Summary '!L20
A38: ='Summary '!D18 | B38: ='Summary '!E18 | C38: ='Summary '!F18 | E38: ='Summary '!J21 | F38: ='Summary '!K21 | G38: ='Summary '!L21
A39: SIP of 50000*36=1800000 , Maturity Value Would be | B39: 2767450 | E39: ='Summary '!J22 | F39: ='Summary '!K22 | G39: ='Summary '!L22
E40: Others
A41: Flexi Cap - Funds | B41: 3-Year Return | C41: 1-Year Return | E41: Multi Asset | F41: 3-Year Return | G41: 1-Year Return
A42: ='Summary '!D20 | B42: 0.1778 | C42: 0.0382 | E42: Nifty 500 | F42: 0.1191 | G42: 0.0263
...

Sheet Table 2 FD PMS AIF
B2: Financial Product Catalog: A Ready Reckoner , As on 04th September 2026
B4: Credit ratings assessed by (e.g., CRISIL, ICRA, CARE)
B6: Corporate FD's
B7: Institution | C7: 3-Year FD Rate | E7: 1-Year FD Rate
B8: SBI Bank FD | C8: 6.30% - 6.80% | E8: 6.25% - 6.75%
B9: Shriram Finance | C9: 7.50% – 8.00% | E9: 6.85% – 7.35%
B10: Bajaj Finance | C10: 7.40% – 7.75% | E10: 6.60% – 6.95%
B11: PNB Housing Finance | C11: 7.10% – 7.35% | E11: 6.70% – 6.95%
B12: ICICI Home Finance | C12: 7.10% -7.45% | E12: 6.85% – 7.20%
B13: LIC Housing Finance | C13: 6.85% -7.10% | E13: 6.70% – 6.95%
B14: Capital Gain Bonds/NCD
B15: Index Name | C15: 5-Year Return
B16: NIFTY 10 Year Benchmark G-Sec Index | C16: 0.0536
B17: Issuer | C17: Interest Rate | D17: Tenure
B18: IRFC | C18: 5.25% p.a. | D18: 5 years
B19: PFC | C19: 5.25% p.a. | D19: 5 years
B20: REC | C20: 5.25% p.a. | D20: 5 years
B22: RBI Floating Rate Savings Bond | D22: Interest Rate
B23: HDFC | D23: 8.05% p.a.

Sheet Summary 
B2: Equity | H2: Debt
B3: Category | C3: Rank | D3: Fund | E3: 3 year Return | F3: 1 year Return | H3: Category | I3: Rank | J3: Fund | K3: 3 year Return | L3: 1 year Return
B4: Large Cap | C4: 1 | D4: =VLOOKUP(C4, 'Fund Ranking_Equity'!$C$5:$D$12,2,FALSE) | E4: =_xlfn.CONCAT((ROUND(VLOOKUP($D4,'Fund Ranking_Equity'!$B$6:$T$137,5,FALSE),2)),"%") | F4: =_xlfn.CONCAT((ROUND(VLOOKUP($D4,'Fund Ranking_Equity'!$B$6:$T$137,4,FALSE),2)),"%") | H4: ='Fund Ranking Criteria'!C24 | I4: 1 | J4: =VLOOKUP($I4, 'Fund Ranking_Debt'!$C$7:$N$13,3,FALSE) | K4: =_xlfn.CONCAT(ROUND(VLOOKUP($I4, 'Fund Ranking_Debt'!$C$7:$N$13,12,FALSE),2),"%") | L4: =_xlfn.CONCAT(ROUND(VLOOKUP($I4, 'Fund Ranking_Debt'!$C$7:$N$13,10,FALSE),2),"%")
C5: 2 | D5: =VLOOKUP(C5, 'Fund Ranking_Equity'!$C$5:$D$12,2,FALSE) | E5: =_xlfn.CONCAT((ROUND(VLOOKUP($D5,'Fund Ranking_Equity'!$B$6:$T$137,5,FALSE),2)),"%") | F5: =_xlfn.CONCAT((ROUND(VLOOKUP($D5,'Fund Ranking_Equity'!$B$6:$T$137,4,FALSE),2)),"%") | I5: 2 | J5: =VLOOKUP($I5, 'Fund Ranking_Debt'!$C$7:$N$13,3,FALSE) | K5: =_xlfn.CONCAT(ROUND(VLOOKUP($I5, 'Fund Ranking_Debt'!$C$7:$N$13,12,FALSE),2),"%") | L5: =_xlfn.CONCAT(ROUND(VLOOKUP($I5, 'Fund Ranking_Debt'!$C$7:$N$13,10,FALSE),2),"%")
C6: 3 | D6: =VLOOKUP(C6, 'Fund Ranking_Equity'!$C$5:$D$12,2,FALSE) | E6: =_xlfn.CONCAT((ROUND(VLOOKUP($D6,'Fund Ranking_Equity'!$B$6:$T$137,5,FALSE),2)),"%") | F6: =_xlfn.CONCAT((ROUND(VLOOKUP($D6,'Fund Ranking_Equity'!$B$6:$T$137,4,FALSE),2)),"%") | I6: 3 | J6: =VLOOKUP($I6, 'Fund Ranking_Debt'!$C$7:$N$13,3,FALSE) | K6: =_xlfn.CONCAT(ROUND(VLOOKUP($I6, 'Fund Ranking_Debt'!$C$7:$N$13,12,FALSE),2),"%") | L6: =_xlfn.CONCAT(ROUND(VLOOKUP($I6, 'Fund Ranking_Debt'!$C$7:$N$13,10,FALSE),2),"%")
B8: ='Fund Ranking Criteria'!D4 | C8: 1 | D8: =VLOOKUP(C8, 'Fund Ranking_Equity'!$C$17:$D$23,2,FALSE) | E8: =_xlfn.CONCAT((ROUND(VLOOKUP($D8,'Fund Ranking_Equity'!$B$6:$T$137,5,FALSE),2)),"%") | F8: =_xlfn.CONCAT((ROUND(VLOOKUP($D8,'Fund Ranking_Equity'!$B$6:$T$137,4,FALSE),2)),"%") | H8: ='Fund Ranking Criteria'!D24 | I8: 1 | J8: =VLOOKUP($I8, 'Fund Ranking_Debt'!$C$19:$N$25,3,FALSE) | K8: =_xlfn.CONCAT(ROUND(VLOOKUP($I8, 'Fund Ranking_Debt'!$C$19:$N$25,12,FALSE),2),"%") | L8: =_xlfn.CONCAT(ROUND(VLOOKUP($I8, 'Fund Ranking_Debt'!$C$19:$N$25,10,FALSE),2),"%")
C9: 2 | D9: =VLOOKUP(C9, 'Fund Ranking_Equity'!$C$17:$D$23,2,FALSE) | E9: =_xlfn.CONCAT((ROUND(VLOOKUP($D9,'Fund Ranking_Equity'!$B$6:$T$137,5,FALSE),2)),"%") | F9: =_xlfn.CONCAT((ROUND(VLOOKUP($D9,'Fund Ranking_Equity'!$B$6:$T$137,4,FALSE),2)),"%") | I9: 2 | J9: =VLOOKUP($I9, 'Fund Ranking_Debt'!$C$19:$N$25,3,FALSE) | K9: =_xlfn.CONCAT(ROUND(VLOOKUP($I9, 'Fund Ranking_Debt'!$C$19:$N$25,12,FALSE),2),"%") | L9: =_xlfn.CONCAT(ROUND(VLOOKUP($I9, 'Fund Ranking_Debt'!$C$19:$N$25,10,FALSE),2),"%")
C10: 3 | D10: =VLOOKUP(C10, 'Fund Ranking_Equity'!$C$17:$D$23,2,FALSE) | E10: =_xlfn.CONCAT((ROUND(VLOOKUP($D10,'Fund Ranking_Equity'!$B$6:$T$137,5,FALSE),2)),"%") | F10: =_xlfn.CONCAT((ROUND(VLOOKUP($D10,'Fund Ranking_Equity'!$B$6:$T$137,4,FALSE),2)),"%") | I10: 3 | J10: =VLOOKUP($I10, 'Fund Ranking_Debt'!$C$19:$N$25,3,FALSE) | K10: =_xlfn.CONCAT(ROUND(VLOOKUP($I10, 'Fund Ranking_Debt'!$C$19:$N$25,12,FALSE),2),"%") | L10: =_xlfn.CONCAT(ROUND(VLOOKUP($I10, 'Fund Ranking_Debt'!$C$19:$N$25,10,FALSE),2),"%")
B12: ='Fund Ranking Criteria'!F4 | C12: 1 | D12: =VLOOKUP(C12, 'Fund Ranking_Equity'!$C$28:$D$34,2,FALSE) | E12: =_xlfn.CONCAT((ROUND(VLOOKUP($D12,'Fund Ranking_Equity'!$B$6:$T$137,5,FALSE),2)),"%") | F12: =_xlfn.CONCAT((ROUND(VLOOKUP($D12,'Fund Ranking_Equity'!$B$6:$T$137,4,FALSE),2)),"%") | H12: ='Fund Ranking Criteria'!E24 | I12: 1 | J12: =VLOOKUP($I12, 'Fund Ranking_Debt'!$C$31:$N$37,3,FALSE) | K12: =_xlfn.CONCAT(ROUND(VLOOKUP($I12, 'Fund Ranking_Debt'!$C$31:$N$37,12,FALSE),2),"%") | L12: =_xlfn.CONCAT(ROUND(VLOOKUP($I12, 'Fund Ranking_Debt'!$C$31:$N$37,10,FALSE),2),"%")
C13: 2 | D13: =VLOOKUP(C13, 'Fund Ranking_Equity'!$C$28:$D$34,2,FALSE) | E13: =_xlfn.CONCAT((ROUND(VLOOKUP($D13,'Fund Ranking_Equity'!$B$6:$T$137,5,FALSE),2)),"%") | F13: =_xlfn.CONCAT((ROUND(VLOOKUP($D13,'Fund Ranking_Equity'!$B$6:$T$137,4,FALSE),2)),"%") | I13: 2 | J13: =VLOOKUP($I13, 'Fund Ranking_Debt'!$C$31:$N$37,3,FALSE) | K13: =_xlfn.CONCAT(ROUND(VLOOKUP($I13, 'Fund Ranking_Debt'!$C$31:$N$37,12,FALSE),2),"%") | L13: =_xlfn.CONCAT(ROUND(VLOOKUP($I13, 'Fund Ranking_Debt'!$C$31:$N$37,10,FALSE),2),"%")
C14: 3 | D14: =VLOOKUP(C14, 'Fund Ranking_Equity'!$C$28:$D$34,2,FALSE) | E14: =_xlfn.CONCAT((ROUND(VLOOKUP($D14,'Fund Ranking_Equity'!$B$6:$T$137,5,FALSE),2)),"%") | F14: =_xlfn.CONCAT((ROUND(VLOOKUP($D14,'Fund Ranking_Equity'!$B$6:$T$137,4,FALSE),2)),"%") | I14: 3 | J14: =VLOOKUP($I14, 'Fund Ranking_Debt'!$C$31:$N$37,3,FALSE) | K14: =_xlfn.CONCAT(ROUND(VLOOKUP($I14, 'Fund Ranking_Debt'!$C$31:$N$37,12,FALSE),2),"%") | L14: =_xlfn.CONCAT(ROUND(VLOOKUP($I14, 'Fund Ranking_Debt'!$C$31:$N$37,10,FALSE),2),"%")
B16: ='Fund Ranking Criteria'!G4 | C16: 1 | D16: =VLOOKUP(C16, 'Fund Ranking_Equity'!$C$39:$D$45,2,FALSE) | E16: =_xlfn.CONCAT((ROUND(VLOOKUP($D16,'Fund Ranking_Equity'!$B$6:$T$137,5,FALSE),2)),"%") | F16: =_xlfn.CONCAT((ROUND(VLOOKUP($D16,'Fund Ranking_Equity'!$B$6:$T$137,4,FALSE),2)),"%") | H16: ='Fund Ranking Criteria'!F24 | I16: 1 | J16: =VLOOKUP($I16, 'Fund Ranking_Debt'!$C$42:$N$48,3,FALSE) | K16: =_xlfn.CONCAT(ROUND(VLOOKUP($I16, 'Fund Ranking_Debt'!$C$42:$N$48,12,FALSE),2),"%") | L16: =_xlfn.CONCAT(ROUND(VLOOKUP($I16, 'Fund Ranking_Debt'!$C$42:$N$48,10,FALSE),2),"%")
C17: 2 | D17: =VLOOKUP(C17, 'Fund Ranking_Equity'!$C$39:$D$45,2,FALSE) | E17: =_xlfn.CONCAT((ROUND(VLOOKUP($D17,'Fund Ranking_Equity'!$B$6:$T$137,5,FALSE),2)),"%") | F17: =_xlfn.CONCAT((ROUND(VLOOKUP($D17,'Fund Ranking_Equity'!$B$6:$T$137,4,FALSE),2)),"%") | I17: 2 | J17: =VLOOKUP($I17, 'Fund Ranking_Debt'!$C$42:$N$48,3,FALSE) | K17: =_xlfn.CONCAT(ROUND(VLOOKUP($I17, 'Fund Ranking_Debt'!$C$42:$N$48,12,FALSE),2),"%") | L17: =_xlfn.CONCAT(ROUND(VLOOKUP($I17, 'Fund Ranking_Debt'!$C$42:$N$48,10,FALSE),2),"%")
C18: 3 | D18: =VLOOKUP(C18, 'Fund Ranking_Equity'!$C$39:$D$45,2,FALSE) | E18: =_xlfn.CONCAT((ROUND(VLOOKUP($D18,'Fund Ranking_Equity'!$B$6:$T$137,5,FALSE),2)),"%") | F18: =_xlfn.CONCAT((ROUND(VLOOKUP($D18,'Fund Ranking_Equity'!$B$6:$T$137,4,FALSE),2)),"%") | I18: 3 | J18: =VLOOKUP($I18, 'Fund Ranking_Debt'!$C$42:$N$48,3,FALSE) | K18: =_xlfn.CONCAT(ROUND(VLOOKUP($I18, 'Fund Ranking_Debt'!$C$42:$N$48,12,FALSE),2),"%") | L18: =_xlfn.CONCAT(ROUND(VLOOKUP($I18, 'Fund Ranking_Debt'!$C$42:$N$48,10,FALSE),2),"%")
B20: Flexicap | C20: 1 | D20: =VLOOKUP(C20, 'Fund Ranking_Equity'!$C$50:$D$53,2,FALSE) | E20: =_xlfn.CONCAT((ROUND(VLOOKUP($D20,'Fund Ranking_Equity'!$B$6:$T$137,5,FALSE),2)),"%") | F20: =_xlfn.CONCAT((ROUND(VLOOKUP($D20,'Fund Ranking_Equity'!$B$6:$T$137,4,FALSE),2)),"%") | H20: Medium to Long Duration Fund | I20: 1 | J20: =VLOOKUP($I20, 'Fund Ranking_Debt'!$C$53:$N$59,3,FALSE) | K20: =_xlfn.CONCAT(ROUND(VLOOKUP($I20, 'Fund Ranking_Debt'!$C$53:$N$59,12,FALSE),2),"%") | L20: =_xlfn.CONCAT(ROUND(VLOOKUP($I20, 'Fund Ranking_Debt'!$C$53:$N$59,10,FALSE),2),"%")
C21: 2 | D21: =VLOOKUP(C21, 'Fund Ranking_Equity'!$C$50:$D$53,2,FALSE) | E21: =_xlfn.CONCAT((ROUND(VLOOKUP($D21,'Fund Ranking_Equity'!$B$6:$T$137,5,FALSE),2)),"%") | F21: =_xlfn.CONCAT((ROUND(VLOOKUP($D21,'Fund Ranking_Equity'!$B$6:$T$137,4,FALSE),2)),"%") | I21: 2 | J21: =VLOOKUP($I21, 'Fund Ranking_Debt'!$C$53:$N$59,3,FALSE) | K21: =_xlfn.CONCAT(ROUND(VLOOKUP($I21, 'Fund Ranking_Debt'!$C$53:$N$59,12,FALSE),2),"%") | L21: =_xlfn.CONCAT(ROUND(VLOOKUP($I21, 'Fund Ranking_Debt'!$C$53:$N$59,10,FALSE),2),"%")
C22: 3 | D22: =VLOOKUP(C22, 'Fund Ranking_Equity'!$C$50:$D$56,2,FALSE) | E22: =_xlfn.CONCAT((ROUND(VLOOKUP($D22,'Fund Ranking_Equity'!$B$6:$T$137,5,FALSE),2)),"%") | F22: =_xlfn.CONCAT((ROUND(VLOOKUP($D22,'Fund Ranking_Equity'!$B$6:$T$137,4,FALSE),2)),"%") | I22: 3 | J22: =VLOOKUP($I22, 'Fund Ranking_Debt'!$C$53:$N$59,3,FALSE) | K22: =_xlfn.CONCAT(ROUND(VLOOKUP($I22, 'Fund Ranking_Debt'!$C$53:$N$59,12,FALSE),2),"%") | L22: =_xlfn.CONCAT(ROUND(VLOOKUP($I22, 'Fund Ranking_Debt'!$C$53:$N$59,10,FALSE),2),"%")
B24: ='Fund Ranking Criteria'!H4 | C24: 1 | D24: =VLOOKUP($C24,'Fund Ranking_Equity'!$C$61:$E$67,2,FALSE) | E24: =_xlfn.CONCAT((ROUND(VLOOKUP($D24,'Fund Ranking_Equity'!$B$6:$T$137,5,FALSE),2)),"%") | F24: =_xlfn.CONCAT((ROUND(VLOOKUP($D24,'Fund Ranking_Equity'!$B$6:$T$137,4,FALSE),2)),"%")
C25: 2 | D25: =VLOOKUP($C25,'Fund Ranking_Equity'!$C$61:$E$67,2,FALSE) | E25: =_xlfn.CONCAT((ROUND(VLOOKUP($D25,'Fund Ranking_Equity'!$B$6:$T$137,5,FALSE),2)),"%") | F25: =_xlfn.CONCAT((ROUND(VLOOKUP($D25,'Fund Ranking_Equity'!$B$6:$T$137,4,FALSE),2)),"%")
C26: 3 | D26: =VLOOKUP($C26,'Fund Ranking_Equity'!$C$61:$E$67,2,FALSE) | E26: =_xlfn.CONCAT((ROUND(VLOOKUP($D26,'Fund Ranking_Equity'!$B$6:$T$137,5,FALSE),2)),"%") | F26: =_xlfn.CONCAT((ROUND(VLOOKUP($D26,'Fund Ranking_Equity'!$B$6:$T$137,4,FALSE),2)),"%")
B28: Multi-Asset | C28: 1 | D28: =VLOOKUP(C28, 'Fund Ranking_Equity'!$C$72:$D$78,2,FALSE) | E28: =_xlfn.CONCAT((ROUND(VLOOKUP($D28,'Fund Ranking_Equity'!$B$6:$T$137,5,FALSE),2)),"%") | F28: =_xlfn.CONCAT((ROUND(VLOOKUP($D28,'Fund Ranking_Equity'!$B$6:$T$137,4,FALSE),2)),"%")
C29: 2 | D29: =VLOOKUP(C29, 'Fund Ranking_Equity'!$C$72:$D$78,2,FALSE) | E29: =_xlfn.CONCAT((ROUND(VLOOKUP($D29,'Fund Ranking_Equity'!$B$6:$T$137,5,FALSE),2)),"%") | F29: =_xlfn.CONCAT((ROUND(VLOOKUP($D29,'Fund Ranking_Equity'!$B$6:$T$137,4,FALSE),2)),"%")
C30: 3 | D30: =VLOOKUP(C30, 'Fund Ranking_Equity'!$C$72:$D$78,2,FALSE) | E30: =_xlfn.CONCAT((ROUND(VLOOKUP($D30,'Fund Ranking_Equity'!$B$6:$T$137,5,FALSE),2)),"%") | F30: =_xlfn.CONCAT((ROUND(VLOOKUP($D30,'Fund Ranking_Equity'!$B$6:$T$137,4,FALSE),2)),"%")
C32: Ranking | D32: Funds (Equity)
B33: Consolidated | C33: 1 | D33: =VLOOKUP(C33,#REF!, 2,FALSE)
C34: 2 | D34: =VLOOKUP(C34,#REF!, 2,FALSE)
C35: =C34+1 | D35: =VLOOKUP(C35,#REF!, 2,FALSE)
C36: =C35+1 | D36: =VLOOKUP(C36,#REF!, 2,FALSE)
C37: =C36+1 | D37: =VLOOKUP(C37,#REF!, 2,FALSE)
C38: =C37+1 | D38: =VLOOKUP(C38,#REF!, 2,FALSE)
C39: =C38+1 | D39: =VLOOKUP(C39,#REF!, 2,FALSE)
C40: =C39+1 | D40: =VLOOKUP(C40,#REF!, 2,FALSE)
C41: =C40+1 | D41: =VLOOKUP(C41,#REF!, 2,FALSE)
C42: =C41+1 | D42: =VLOOKUP(C42,#REF!, 2,FALSE)
B43: Thematic | C43: 1 | D43: =VLOOKUP('Summary '!$C24,'Fund Ranking_Equity'!$C$83:$E$137,2,FALSE) | E43: =_xlfn.CONCAT((ROUND(VLOOKUP($D43,'Fund Ranking_Equity'!$B$6:$T$137,5,FALSE),2)),"%") | F43: =_xlfn.CONCAT((ROUND(VLOOKUP($D43,'Fund Ranking_Equity'!$B$6:$T$137,4,FALSE),2)),"%")
C44: 2 | D44: =VLOOKUP('Summary '!$C25,'Fund Ranking_Equity'!$C$83:$E$137,2,FALSE) | E44: =_xlfn.CONCAT((ROUND(VLOOKUP($D44,'Fund Ranking_Equity'!$B$6:$T$137,5,FALSE),2)),"%") | F44: =_xlfn.CONCAT((ROUND(VLOOKUP($D44,'Fund Ranking_Equity'!$B$6:$T$137,4,FALSE),2)),"%")
C45: 3 | D45: =VLOOKUP('Summary '!$C26,'Fund Ranking_Equity'!$C$83:$E$137,2,FALSE) | E45: =_xlfn.CONCAT((ROUND(VLOOKUP($D45,'Fund Ranking_Equity'!$B$6:$T$137,5,FALSE),2)),"%") | F45: =_xlfn.CONCAT((ROUND(VLOOKUP($D45,'Fund Ranking_Equity'!$B$6:$T$137,4,FALSE),2)),"%")

Sheet Investor Profile
B3: S.No. | C3: Question | D3: Options | E3: Score Assigned | G3: Questions | I3: Investor Profile
B4: Personal & Financial Information | G4: Age | I4: Early Career | J4: Mid-Career | K4: Pre-Retirement | L4: Retirement
B5: 1 | C5: Age | D5: 18-30 | E5: 4 | G5: (Question 1) | I5: 4 | J5: 3 | K5: 2 | L5: 1
D6: 31-45 | E6: 3 | G6: Financial Standing | I6: Limited Resources | J6: Stable Financials | K6: Affluent | L6: HNI/UHNI
D7: 46-60 | E7: 2 | G7: (Question 2+3+4) | I7: <5 | J7: (6 - 8) | K7: (9-12) | L7: 13>
D8: 60+ | E8: 1 | G8: Investment Objectives | I8: Wealth Creation | J8: Regular Income | K8: Safety & Stability | L8: Aggressive Growth
B9: =B5+1 | C9: Annual Income | D9: Below ₹5 lakh | E9: 0 | G9: (Question 6) | I9: 1 | J9: 2 | K9: 3 | L9: 4
D10: ₹5-10 lakh | E10: 1 | G10: Time Horizon | I10: Short Term | J10: Short to Medium Term | K10: Medium Term | L10: Long Term
D11: ₹10-25 lakh | E11: 2 | G11: (Question 7) | I11: 1 | J11: 2 | K11: 3 | L11: 4
D12: ₹25-50 lakh | E12: 3 | G12: Risk Appetite | I12: Conservative | J12: Aggressive
D13: ₹50-100 lakh | E13: 4 | G13: (Question 8) | I13: 1 | J13: 2
D14: Above ₹1 Cr | E14: 5 | G14: Investment Knowledge | I14: Beginner | J14: Basic Knowledge | K14: Moderate Knowledge | L14: Advanced Knowledge
B15: 3 | C15: Annual Family Income | D15: ₹5-10 lakh | E15: 1 | G15: (Question 9 + 10 ) | I15: 2 | J15: 3 | K15: 4 | L15: 5
D16: ₹10-25 lakh | E16: 2
D17: ₹25-50 lakh | E17: 3
D18: ₹50-100 lakh | E18: 4 | G18: Questions | I18: Model Portfolio
D19: Above ₹1 Cr | E19: 5 | G19: Age | I19: Early Career | J19: Mid-Career | K19: Pre-Retirement | L19: Retirement
B20: 4 | C20: Monthly Savings | D20: Less than 10% | E20: 1 | G20: Type of MF | I20: SIP | J20: Lumpsum/SIP | K20: =J20 | L20: =K20
D21: 10%-15% | E21: 2 | G21: Equity:Debt | I21: 80:20 | J21: 70:30 | K21: 50:50 | L21: 40:60
D22: 15-20% | E22: 3 | G22: Suggested Funds: Equity | I22: =_xlfn.CONCAT(Backup!$B$36, ", ",Backup!$B$38,", ",Backup!$B$37, ", ",Backup!$B$40, ", ",Backup!$B$41) | J22: =_xlfn.CONCAT(Backup!$B$35, ", ", Backup!$B$36, ", ",Backup!$B$37, ", ",Backup!$B$40, ", ",Backup!$B$41) | K22: =_xlfn.CONCAT(Backup!$B$35, ", ", Backup!$B$36, ", ",Backup!$B$37, ", ",Backup!$B$40, ", ",Backup!$B$41) | L22: =_xlfn.CONCAT(Backup!$B$35, ", ", Backup!$B$36)
D23: 20-30% | E23: 4 | G23: Suggested Funds: Debt | I23: =_xlfn.CONCAT(Backup!$C$35, " ,",Backup!$C$36) | J23: =_xlfn.CONCAT(Backup!$C$35, " ,",Backup!$C$36, " ,",Backup!$C$37 ) | K23: =_xlfn.CONCAT(Backup!$C$35, " ,",Backup!$C$36, " ,",Backup!$C$37 ) | L23: =_xlfn.CONCAT(Backup!$C$35, " ,",Backup!$C$36, " ,",Backup!$C$37 )
D24: More than 30% | E24: 5 | G24: Financial Standing | I24: Limited Resources | J24: Stable Financials | K24: Affluent | L24: HNI/UHNI
B25: Investment Objective | G25: Type of MF | I25: SIP | J25: Lumpsum/SIP | K25: =J25 | L25: =K25
B26: 6 | C26: Investment Goal | D26: Wealth Creation | E26: 1 | G26: Equity:Debt | I26: 40:60 | J26: 50:50 | K26: 70:30 | L26: 70:30
D27: Income-Oriented | E27: 2 | G27: Suggested Funds: Equity | I27: =L22 | J27: =K22 | K27: =J22 | L27: =_xlfn.CONCAT(Backup!$B$36, ", ",Backup!$B$38,", ",Backup!$B$37, ", ",Backup!$B$40, ", ",Backup!$B$41)
D28: Capital Protection | E28: 3 | G28: Suggested Funds: Debt | I28: =I23 | J28: =L23 | K28: =K23 | L28: =K28
D29: Aggressive Growth | E29: 4 | G29: Investment Objectives | I29: Wealth Creation | J29: Regular Income | K29: Safety & Stability | L29: Aggressive Growth
B30: 7 | C30: Investment Horizon | D30: Less than 1 year | E30: 1 | G30: Type of MF | I30: Lumpsum/SIP | J30: Lumpsum | K30: Lumpsum/SIP | L30: SIP
D31: 1-3 years | E31: 2 | G31: Equity:Debt | I31: =L31 | J31: =J26 | K31: 20:80 | L31: 80:20
D32: 3-5 years | E32: 3 | G32: Suggested Funds: Equity | I32: =J27 | J32: =J27 | K32: =_xlfn.CONCAT(Backup!$B$35, ", ", Backup!$B$36) | L32: =_xlfn.CONCAT(Backup!$B$39, ", ", Backup!$B$38)
D33: 5+ years | E33: 4 | G33: Suggested Funds: Debt | I33: =I28 | J33: =J28 | K33: =I33 | L33: =I43
B34: Risk Appetite | G34: Time Horizon | I34: Short Term | J34: Short to Medium Term | K34: Medium Term | L34: Long Term
B35: 8 | C35: Will you be okay with? | D35: Gain/Loss of 15% | E35: 2 | G35: Type of MF | I35: =I40 | J35: =I35 | K35: =K30 | L35: =K35
D36: Fixed gain of 5% | E36: 1 | G36: Equity:Debt | I36: 80:20 | J36: 50:50 | K36: 50:50 | L36: 20:80
B37: Market Experience | G37: Suggested Funds: Equity | I37: =L32 | J37: =_xlfn.CONCAT(Backup!$B$39, ", ", Backup!$B$38, ", ",Backup!$B$37, ", ",Backup!$B$40, ", ",Backup!$B$41) | K37: =_xlfn.CONCAT(Backup!$B$38, ", ",Backup!$B$37, ", ",Backup!$B$40, ", ",Backup!$B$41) | L37: =_xlfn.CONCAT(Backup!$B$35, ", ", Backup!$B$36)
B38: 9 | C38: Market Experience | D38: No exposure | E38: 1 | G38: Suggested Funds: Debt | I38: =I33 | J38: =J33 | K38: =K33 | L38: =L33
D39: Limited exposure | E39: 2 | G39: Risk Appetite | I39: Conservative | J39: Aggressive
D40: Actively invest or trade | E40: 3 | G40: Type of MF | I40: Lumpsum | J40: SIP
B41: 10 | C41: Knowledge of Investments | D41: Very Little to no knowledge | E41: 1 | G41: Equity:Debt | I41: 20:80 | J41: 80:20
D42: Moderate level of knowledge | E42: 2 | G42: Suggested Funds: Equity | I42: =_xlfn.CONCAT(Backup!$B$37, ", ",Backup!$B$40, ", ",Backup!$B$41, Backup!$B$35, ", ", Backup!$B$36) | J42: =J37
...

Sheet Investor Persona
F2: 2 | G2: 3 | H2: 4 | I2: 5
B3: Quesitons | C3: Option | D3: Points | E3: Persona | F3: Type of MF | G3: Equity:Debt | H3: Suggested Funds: Equity | I3: Suggested Funds: Debt
B4: Age | C4: 18-30 | D4: =VLOOKUP($C4, 'Investor Profile'!$D$5:$E$14,2,FALSE) | E4: {=_xlfn.IFS(D4='Investor Profile'!I5,'Investor Profile'!I4, D4='Investor Profile'!J5, 'Investor Profile'!J4, D4='Investor Profile'!K5, 'Investor Profile'!K4, D4='Investor Profile'!L5, 'Investor Profile'!L4)} | F4: =HLOOKUP('Investor Persona'!$E$4, 'Investor Profile'!$I$19:$L$23,F$2,FALSE) | G4: =HLOOKUP('Investor Persona'!$E$4, 'Investor Profile'!$I$19:$L$23,G$2,FALSE) | H4: =HLOOKUP('Investor Persona'!$E$4, 'Investor Profile'!$I$19:$L$23,H$2,FALSE) | I4: =HLOOKUP('Investor Persona'!$E$4, 'Investor Profile'!$I$19:$L$23,I$2,FALSE)
B5: Annual Income | C5: ₹10-25 lakh | D5: =VLOOKUP($C5, 'Investor Profile'!$D$5:$E$14,2,FALSE) | E5: =IF(SUM($D$5:$D$7)<5,"Limited Resources",IF(SUM($D$5:$D$7)<=8,"Stable Financials",IF(SUM($D$5:$D$7)<=12,"Affluent",IF(SUM($D$5:$D$7)>=13,"HNI/UHNI","")))) | F5: =HLOOKUP('Investor Persona'!$E$5, 'Investor Profile'!$I$24:$L$28,F$2,FALSE) | G5: =HLOOKUP('Investor Persona'!$E$5, 'Investor Profile'!$I$24:$L$28,G$2,FALSE) | H5: =HLOOKUP('Investor Persona'!$E$5, 'Investor Profile'!$I$24:$L$28,H$2,FALSE) | I5: =HLOOKUP('Investor Persona'!$E$5, 'Investor Profile'!$I$24:$L$28,I$2,FALSE)
B6: Annual Family Income | C6: ₹25-50 lakh | D6: =VLOOKUP($C6, 'Investor Profile'!$D$15:$E$19,2,FALSE)
B7: Monthly Savings | C7: Less than 10% | D7: =VLOOKUP($C7, 'Investor Profile'!$D$20:$E$24,2,FALSE)
B8: Investment Goal | C8: Aggressive Growth | D8: =VLOOKUP($C8, 'Investor Profile'!$D$26:$E$33,2,FALSE) | E8: {=_xlfn.IFS(D8='Investor Profile'!I9,'Investor Profile'!I8, D8='Investor Profile'!J9, 'Investor Profile'!J8, D8='Investor Profile'!K9, 'Investor Profile'!K8, D8='Investor Profile'!L9, 'Investor Profile'!L8)} | F8: =HLOOKUP('Investor Persona'!$E$8, 'Investor Profile'!$I$29:$L$33,F$2,FALSE) | G8: =HLOOKUP('Investor Persona'!$E$8, 'Investor Profile'!$I$29:$L$33,G$2,FALSE) | H8: =HLOOKUP('Investor Persona'!$E$8, 'Investor Profile'!$I$29:$L$33,H$2,FALSE) | I8: =HLOOKUP('Investor Persona'!$E$8, 'Investor Profile'!$I$29:$L$33,I$2,FALSE)
B9: Investment Horizon | C9: Less than 1 year | D9: =VLOOKUP($C9, 'Investor Profile'!$D$26:$E$33,2,FALSE) | E9: {=_xlfn.IFS(D9='Investor Profile'!I11,'Investor Profile'!I10, D9='Investor Profile'!J11, 'Investor Profile'!J10, D9='Investor Profile'!K11, 'Investor Profile'!K10, D9='Investor Profile'!L11, 'Investor Profile'!L10)} | F9: =HLOOKUP('Investor Persona'!$E$9, 'Investor Profile'!$I$34:$L$38,F$2,FALSE) | G9: =HLOOKUP('Investor Persona'!$E$9, 'Investor Profile'!$I$34:$L$38,G$2,FALSE) | H9: =HLOOKUP('Investor Persona'!$E$9, 'Investor Profile'!$I$34:$L$38,H$2,FALSE) | I9: =HLOOKUP('Investor Persona'!$E$9, 'Investor Profile'!$I$34:$L$38,I$2,FALSE)
B10: Will you be okay with? | C10: Fixed gain of 5% | D10: =VLOOKUP($C10,'Investor Profile'!$D$35:$E$36,2,FALSE) | E10: =IF(SUM($D$10:$D$10)=1,"Conservative",IF(SUM($D$10:$D$10)=2,"Aggressive","")) | F10: =HLOOKUP('Investor Persona'!$E$10,'Investor Profile'!$I$39:$J$43,F$2,FALSE) | G10: =HLOOKUP('Investor Persona'!$E$10,'Investor Profile'!$I$39:$J$43,G$2,FALSE) | H10: =HLOOKUP('Investor Persona'!$E$10,'Investor Profile'!$I$39:$J$43,H$2,FALSE) | I10: =HLOOKUP('Investor Persona'!$E$10,'Investor Profile'!$I$39:$J$43,I$2,FALSE)
B11: Market Experience | C11: Actively invest or trade | D11: =VLOOKUP($C11, 'Investor Profile'!$D$38:$E$43,2,FALSE) | E11: {=_xlfn.IFS(SUM($D$11:$D$12)='Investor Profile'!I15,'Investor Profile'!I14, SUM($D$11:$D$12)='Investor Profile'!J15, 'Investor Profile'!J14, SUM($D$11:$D$12)='Investor Profile'!K15, 'Investor Profile'!K14, SUM($D$11:$D$12)='Investor Profile'!L15, 'Investor Profile'!L14, SUM($D$11:$D$12)=6, 'Investor Profile'!L14)} | F11: =HLOOKUP('Investor Persona'!$E$11,'Investor Profile'!$I$44:$L$48,F$2,FALSE) | G11: =HLOOKUP('Investor Persona'!$E$11,'Investor Profile'!$I$44:$L$48,G$2,FALSE) | H11: =HLOOKUP('Investor Persona'!$E$11,'Investor Profile'!$I$44:$L$48,H$2,FALSE) | I11: =HLOOKUP('Investor Persona'!$E$11,'Investor Profile'!$I$44:$L$48,I$2,FALSE)
B12: Knowledge of Investments | C12: Extensive investment knowledge | D12: =VLOOKUP($C12, 'Investor Profile'!$D$38:$E$43,2,FALSE)
B14: Investable Surplus
B15: Annual Savings | C15: =10*10^5
B16: Additonal Funds avbl | C16: =20*10^5

Sheet Fund Ranking_Equity
B1: (Match with morningstar)
B2: Model Portfolio | E2: 2 | F2: =E2+1 | G2: =F2+1 | H2: =G2+1 | I2: =H2+1 | J2: =I2+1 | K2: =J2+1 | L2: =K2+1 | M2: =L2+1 | ... O2: =N2+1
B3: Equity Large Cap
E4: Actuals | M4: Normalized
B5: Funds | C5: Rank | E5: 1 Yr Ret (%) | F5: 3 Yr Ret (%) | G5: 5 Yr Ret (%) | H5: 10 Yr Ret (%) | I5: Sharpe | J5: Alpha | K5: Beta | L5: SD | M5: =F5 | N5: =G5 | O5: =H5 | P5: Sharpe | Q5: Alpha | R5: Beta | S5: SD | T5: Score
B6: Aditya Birla Sun Life Large Cap Fund - Reg - Growth | C6: =RANK(T6,$T$6:$T$12,0) | D6: =B6 | E6: -3.3024 | F6: 8.5427 | G6: 8.5207 | H6: 10.6111 | I6: 0.030286051 | J6: 0.011346877 | K6: 0.98601939 | L6: 12.119173 | M6: =(F6-MIN(F$6:F$12))/(MAX(F$6:F$12)-MIN(F$6:F$12)) | N6: =(G6-MIN(G$6:G$12))/(MAX(G$6:G$12)-MIN(G$6:G$12)) | O6: =(H6-MIN(H$6:H$12))/(MAX(H$6:H$12)-MIN(H$6:H$12)) | P6: =(I6-MIN(I$6:I$12))/(MAX(I$6:I$12)-MIN(I$6:I$12)) | Q6: =(J6-MIN(J$6:J$12))/(MAX(J$6:J$12)-MIN(J$6:J$12)) | R6: =(MAX(K$6:K$12)-K6)/(MAX(K$6:K$12)-MIN(K$6:K$12)) | S6: =(MAX(L$6:L$12)-L6)/(MAX(L$6:L$12)-MIN(L$6:L$12)) | T6: =(M6*'Fund Ranking Criteria'!$C$9)+('Fund Ranking_Equity'!N6*'Fund Ranking Criteria'!$C$10)+('Fund Ranking_Equity'!O6*'Fund Ranking Criteria'!$C$11)+('Fund Ranking_Equity'!P6*'Fund Ranking Criteria'!$C$16)+('Fund Ranking_Equity'!Q6*'Fund Ranking Criteria'!$C$12)+('Fund Ranking_Equity'!R6*'Fund Ranking Criteria'!$C$14)+('Fund Ranking_Equity'!S6*'Fund Ranking Criteria'!$C$15) | Z6: 1 | AA6: 21 | AB6: =(Z6-MIN(Z$6:Z$10))/(MAX(Z$6:Z$10)-MIN(R$6:R$12)) | AC6: =(AA6-MIN(AA$6:AA$10))/(MAX(AA$6:AA$10)-MIN(S$6:S$12))
B7: HDFC Large Cap Fund - Growth | C7: =RANK(T7,$T$6:$T$12,0) | D7: =B7 | E7: -2.1604 | F7: 8.3548 | G7: 10.6762 | H7: 11.4821 | I7: 0.030153905 | J7: 0.012975393 | K7: 0.95099567 | L7: 11.807294 | M7: =(F7-MIN(F$6:F$12))/(MAX(F$6:F$12)-MIN(F$6:F$12)) | N7: =(G7-MIN(G$6:G$12))/(MAX(G$6:G$12)-MIN(G$6:G$12)) | O7: =(H7-MIN(H$6:H$12))/(MAX(H$6:H$12)-MIN(H$6:H$12)) | P7: =(I7-MIN(I$6:I$12))/(MAX(I$6:I$12)-MIN(I$6:I$12)) | Q7: =(J7-MIN(J$6:J$12))/(MAX(J$6:J$12)-MIN(J$6:J$12)) | R7: =(MAX(K$6:K$12)-K7)/(MAX(K$6:K$12)-MIN(K$6:K$12)) | S7: =(MAX(L$6:L$12)-L7)/(MAX(L$6:L$12)-MIN(L$6:L$12)) | T7: =(M7*'Fund Ranking Criteria'!$C$9)+('Fund Ranking_Equity'!N7*'Fund Ranking Criteria'!$C$10)+('Fund Ranking_Equity'!O7*'Fund Ranking Criteria'!$C$11)+('Fund Ranking_Equity'!P7*'Fund Ranking Criteria'!$C$16)+('Fund Ranking_Equity'!Q7*'Fund Ranking Criteria'!$C$12)+('Fund Ranking_Equity'!R7*'Fund Ranking Criteria'!$C$14)+('Fund Ranking_Equity'!S7*'Fund Ranking Criteria'!$C$15) | Z7: 2 | AA7: 22 | AB7: =(Z7-MIN(Z$6:Z$10))/(MAX(Z$6:Z$10)-MIN(R$6:R$12)) | AC7: =(AA7-MIN(AA$6:AA$10))/(MAX(AA$6:AA$10)-MIN(S$6:S$12))
B8: ICICI Prudential Large Cap Fund - Growth | C8: =RANK(T8,$T$6:$T$12,0) | D8: =B8 | E8: -4.406 | F8: 9.9317 | G8: 10.6454 | H8: 12.3989 | I8: 0.040637863 | J8: 0.13241847 | K8: 0.92842956 | L8: 11.500079 | M8: =(F8-MIN(F$6:F$12))/(MAX(F$6:F$12)-MIN(F$6:F$12)) | N8: =(G8-MIN(G$6:G$12))/(MAX(G$6:G$12)-MIN(G$6:G$12)) | O8: =(H8-MIN(H$6:H$12))/(MAX(H$6:H$12)-MIN(H$6:H$12)) | P8: =(I8-MIN(I$6:I$12))/(MAX(I$6:I$12)-MIN(I$6:I$12)) | Q8: =(J8-MIN(J$6:J$12))/(MAX(J$6:J$12)-MIN(J$6:J$12)) | R8: =(MAX(K$6:K$12)-K8)/(MAX(K$6:K$12)-MIN(K$6:K$12)) | S8: =(MAX(L$6:L$12)-L8)/(MAX(L$6:L$12)-MIN(L$6:L$12)) | T8: =(M8*'Fund Ranking Criteria'!$C$9)+('Fund Ranking_Equity'!N8*'Fund Ranking Criteria'!$C$10)+('Fund Ranking_Equity'!O8*'Fund Ranking Criteria'!$C$11)+('Fund Ranking_Equity'!P8*'Fund Ranking Criteria'!$C$16)+('Fund Ranking_Equity'!Q8*'Fund Ranking Criteria'!$C$12)+('Fund Ranking_Equity'!R8*'Fund Ranking Criteria'!$C$14)+('Fund Ranking_Equity'!S8*'Fund Ranking Criteria'!$C$15) | Z8: 3 | AA8: 23 | AB8: =(Z8-MIN(Z$6:Z$10))/(MAX(Z$6:Z$10)-MIN(R$6:R$12)) | AC8: =(AA8-MIN(AA$6:AA$10))/(MAX(AA$6:AA$10)-MIN(S$6:S$12))
B9: Kotak Large Cap Fund - Reg - Growth | C9: =RANK(T9,$T$6:$T$12,0) | D9: =B9 | E9: -2.5281 | F9: 8.9158 | G9: 8.1174 | H9: 11.2829 | I9: 0.032612987 | J9: 0.038582109 | K9: 0.98143304 | L9: 12.038844 | M9: =(F9-MIN(F$6:F$12))/(MAX(F$6:F$12)-MIN(F$6:F$12)) | N9: =(G9-MIN(G$6:G$12))/(MAX(G$6:G$12)-MIN(G$6:G$12)) | O9: =(H9-MIN(H$6:H$12))/(MAX(H$6:H$12)-MIN(H$6:H$12)) | P9: =(I9-MIN(I$6:I$12))/(MAX(I$6:I$12)-MIN(I$6:I$12)) | Q9: =(J9-MIN(J$6:J$12))/(MAX(J$6:J$12)-MIN(J$6:J$12)) | R9: =(MAX(K$6:K$12)-K9)/(MAX(K$6:K$12)-MIN(K$6:K$12)) | S9: =(MAX(L$6:L$12)-L9)/(MAX(L$6:L$12)-MIN(L$6:L$12)) | T9: =(M9*'Fund Ranking Criteria'!$C$9)+('Fund Ranking_Equity'!N9*'Fund Ranking Criteria'!$C$10)+('Fund Ranking_Equity'!O9*'Fund Ranking Criteria'!$C$11)+('Fund Ranking_Equity'!P9*'Fund Ranking Criteria'!$C$16)+('Fund Ranking_Equity'!Q9*'Fund Ranking Criteria'!$C$12)+('Fund Ranking_Equity'!R9*'Fund Ranking Criteria'!$C$14)+('Fund Ranking_Equity'!S9*'Fund Ranking Criteria'!$C$15) | Z9: 4 | AA9: 24 | AB9: =(Z9-MIN(Z$6:Z$10))/(MAX(Z$6:Z$10)-MIN(R$6:R$12)) | AC9: =(AA9-MIN(AA$6:AA$10))/(MAX(AA$6:AA$10)-MIN(S$6:S$12))
B10: Nippon India Large Cap Fund - Reg - Growth | C10: =RANK(T10,$T$6:$T$12,0) | D10: =B10 | E10: -4.4223 | F10: 9.5258 | G10: 12.2847 | H10: 12.8674 | I10: 0.037994518 | J10: 0.1067531 | K10: 1.0012674 | L10: 12.298748 | M10: =(F10-MIN(F$6:F$12))/(MAX(F$6:F$12)-MIN(F$6:F$12)) | N10: =(G10-MIN(G$6:G$12))/(MAX(G$6:G$12)-MIN(G$6:G$12)) | O10: =(H10-MIN(H$6:H$12))/(MAX(H$6:H$12)-MIN(H$6:H$12)) | P10: =(I10-MIN(I$6:I$12))/(MAX(I$6:I$12)-MIN(I$6:I$12)) | Q10: =(J10-MIN(J$6:J$12))/(MAX(J$6:J$12)-MIN(J$6:J$12)) | R10: =(MAX(K$6:K$12)-K10)/(MAX(K$6:K$12)-MIN(K$6:K$12)) | S10: =(MAX(L$6:L$12)-L10)/(MAX(L$6:L$12)-MIN(L$6:L$12)) | T10: =(M10*'Fund Ranking Criteria'!$C$9)+('Fund Ranking_Equity'!N10*'Fund Ranking Criteria'!$C$10)+('Fund Ranking_Equity'!O10*'Fund Ranking Criteria'!$C$11)+('Fund Ranking_Equity'!P10*'Fund Ranking Criteria'!$C$16)+('Fund Ranking_Equity'!Q10*'Fund Ranking Criteria'!$C$12)+('Fund Ranking_Equity'!R10*'Fund Ranking Criteria'!$C$14)+('Fund Ranking_Equity'!S10*'Fund Ranking Criteria'!$C$15) | Z10: 5 | AA10: 25 | AB10: =(Z10-MIN(Z$6:Z$10))/(MAX(Z$6:Z$10)-MIN(R$6:R$12)) | AC10: =(AA10-MIN(AA$6:AA$10))/(MAX(AA$6:AA$10)-MIN(S$6:S$12))
B11: SBI Large Cap Fund - Growth | C11: =RANK(T11,$T$6:$T$12,0) | D11: =B11 | E11: -1.8491 | F11: 7.9606 | G11: 8.5208 | H11: 10.8213 | I11: 0.027356568 | J11: -0.018169041 | K11: 0.89356034 | L11: 11.097158 | M11: =(F11-MIN(F$6:F$12))/(MAX(F$6:F$12)-MIN(F$6:F$12)) | N11: =(G11-MIN(G$6:G$12))/(MAX(G$6:G$12)-MIN(G$6:G$12)) | O11: =(H11-MIN(H$6:H$12))/(MAX(H$6:H$12)-MIN(H$6:H$12)) | P11: =(I11-MIN(I$6:I$12))/(MAX(I$6:I$12)-MIN(I$6:I$12)) | Q11: =(J11-MIN(J$6:J$12))/(MAX(J$6:J$12)-MIN(J$6:J$12)) | R11: =(MAX(K$6:K$12)-K11)/(MAX(K$6:K$12)-MIN(K$6:K$12)) | S11: =(MAX(L$6:L$12)-L11)/(MAX(L$6:L$12)-MIN(L$6:L$12)) | T11: =(M11*'Fund Ranking Criteria'!$C$9)+('Fund Ranking_Equity'!N11*'Fund Ranking Criteria'!$C$10)+('Fund Ranking_Equity'!O11*'Fund Ranking Criteria'!$C$11)+('Fund Ranking_Equity'!P11*'Fund Ranking Criteria'!$C$16)+('Fund Ranking_Equity'!Q11*'Fund Ranking Criteria'!$C$12)+('Fund Ranking_Equity'!R11*'Fund Ranking Criteria'!$C$14)+('Fund Ranking_Equity'!S11*'Fund Ranking Criteria'!$C$15)
B12: UTI Large Cap Fund - Growth | C12: =RANK(T12,$T$6:$T$12,0) | D12: =B12 | E12: -5.1646 | F12: 6.3548 | G12: 5.9941 | H12: 10.3038 | I12: 0.01718147 | J12: -0.14159306 | K12: 0.95528544 | L12: 11.779076 | M12: =(F12-MIN(F$6:F$12))/(MAX(F$6:F$12)-MIN(F$6:F$12)) | N12: =(G12-MIN(G$6:G$12))/(MAX(G$6:G$12)-MIN(G$6:G$12)) | O12: =(H12-MIN(H$6:H$12))/(MAX(H$6:H$12)-MIN(H$6:H$12)) | P12: =(I12-MIN(I$6:I$12))/(MAX(I$6:I$12)-MIN(I$6:I$12)) | Q12: =(J12-MIN(J$6:J$12))/(MAX(J$6:J$12)-MIN(J$6:J$12)) | R12: =(MAX(K$6:K$12)-K12)/(MAX(K$6:K$12)-MIN(K$6:K$12)) | S12: =(MAX(L$6:L$12)-L12)/(MAX(L$6:L$12)-MIN(L$6:L$12)) | T12: =(M12*'Fund Ranking Criteria'!$C$9)+('Fund Ranking_Equity'!N12*'Fund Ranking Criteria'!$C$10)+('Fund Ranking_Equity'!O12*'Fund Ranking Criteria'!$C$11)+('Fund Ranking_Equity'!P12*'Fund Ranking Criteria'!$C$16)+('Fund Ranking_Equity'!Q12*'Fund Ranking Criteria'!$C$12)+('Fund Ranking_Equity'!R12*'Fund Ranking Criteria'!$C$14)+('Fund Ranking_Equity'!S12*'Fund Ranking Criteria'!$C$15)
B14: Equity Large & Mid Cap
E15: Actuals | M15: Normalized
B16: Funds | C16: Rank | E16: 1 Yr Ret (%) | F16: 3 Yr Ret (%) | G16: 5 Yr Ret (%) | H16: 10 Yr Ret (%) | I16: Sharpe | J16: Alpha | K16: Beta | L16: SD | M16: =F16 | N16: =G16 | O16: =H16 | P16: Sharpe | Q16: Alpha | R16: Beta | S16: SD
B17: SBI Large & Midcap Fund - Growth | C17: =RANK(T17,$T$17:$T$23,0) | D17: =B17 | E17: 1.8685 | F17: 11.1823 | G17: 12.6518 | H17: 13.5115 | I17: 0.047767139 | J17: -0.099158638 | K17: 0.82201619 | L17: 11.944114 | M17: =(F17-MIN(F$17:F$23))/(MAX(F$17:F$23)-MIN(F$17:F$23)) | N17: =(G17-MIN(G$17:G$23))/(MAX(G$17:G$23)-MIN(G$17:G$23)) | O17: =(H17-MIN(H$17:H$23))/(MAX(H$17:H$23)-MIN(H$17:H$23)) | P17: =(I17-MIN(I$17:I$23))/(MAX(I$17:I$23)-MIN(I$17:I$23)) | Q17: =(J17-MIN(J$17:J$23))/(MAX(J$17:J$23)-MIN(J$17:J$23)) | R17: =(MAX(K$17:K$23)-K17)/(MAX(K$17:K$23)-MIN(K$17:K$23)) | S17: =(MAX(L$17:L$23)-L17)/(MAX(L$17:L$23)-MIN(L$17:L$23)) | T17: =(M17*'Fund Ranking Criteria'!$D$9)+('Fund Ranking_Equity'!N17*'Fund Ranking Criteria'!$D$10)+('Fund Ranking_Equity'!O17*'Fund Ranking Criteria'!$D$11)+('Fund Ranking_Equity'!P17*'Fund Ranking Criteria'!$D$16)+('Fund Ranking_Equity'!Q17*'Fund Ranking Criteria'!$D$12)+('Fund Ranking_Equity'!R17*'Fund Ranking Criteria'!$D$14)+('Fund Ranking_Equity'!S17*'Fund Ranking Criteria'!$D$15)
B18: Kotak Large & Midcap Fund - Reg - Growth | C18: =RANK(T18,$T$17:$T$23,0) | D18: =B18 | E18: 3.9908 | F18: 13.1089 | G18: 12.5279 | H18: 14.1551 | I18: 0.053754657 | J18: -0.097868865 | K18: 0.9465684 | L18: 13.810969 | M18: =(F18-MIN(F$17:F$23))/(MAX(F$17:F$23)-MIN(F$17:F$23)) | N18: =(G18-MIN(G$17:G$23))/(MAX(G$17:G$23)-MIN(G$17:G$23)) | O18: =(H18-MIN(H$17:H$23))/(MAX(H$17:H$23)-MIN(H$17:H$23)) | P18: =(I18-MIN(I$17:I$23))/(MAX(I$17:I$23)-MIN(I$17:I$23)) | Q18: =(J18-MIN(J$17:J$23))/(MAX(J$17:J$23)-MIN(J$17:J$23)) | R18: =(MAX(K$17:K$23)-K18)/(MAX(K$17:K$23)-MIN(K$17:K$23)) | S18: =(MAX(L$17:L$23)-L18)/(MAX(L$17:L$23)-MIN(L$17:L$23)) | T18: =(M18*'Fund Ranking Criteria'!$D$9)+('Fund Ranking_Equity'!N18*'Fund Ranking Criteria'!$D$10)+('Fund Ranking_Equity'!O18*'Fund Ranking Criteria'!$D$11)+('Fund Ranking_Equity'!P18*'Fund Ranking Criteria'!$D$16)+('Fund Ranking_Equity'!Q18*'Fund Ranking Criteria'!$D$12)+('Fund Ranking_Equity'!R18*'Fund Ranking Criteria'!$D$14)+('Fund Ranking_Equity'!S18*'Fund Ranking Criteria'!$D$15)
B19: HDFC Large and Mid Cap Fund - Growth | C19: =RANK(T19,$T$17:$T$23,0) | D19: =B19 | E19: 5.9804 | F19: 14.6467 | G19: 15.5715 | H19: 14.5721 | I19: 0.058562372 | J19: 0.022102491 | K19: 0.97585277 | L19: 14.802668 | M19: =(F19-MIN(F$17:F$23))/(MAX(F$17:F$23)-MIN(F$17:F$23)) | N19: =(G19-MIN(G$17:G$23))/(MAX(G$17:G$23)-MIN(G$17:G$23)) | O19: =(H19-MIN(H$17:H$23))/(MAX(H$17:H$23)-MIN(H$17:H$23)) | P19: =(I19-MIN(I$17:I$23))/(MAX(I$17:I$23)-MIN(I$17:I$23)) | Q19: =(J19-MIN(J$17:J$23))/(MAX(J$17:J$23)-MIN(J$17:J$23)) | R19: =(MAX(K$17:K$23)-K19)/(MAX(K$17:K$23)-MIN(K$17:K$23)) | S19: =(MAX(L$17:L$23)-L19)/(MAX(L$17:L$23)-MIN(L$17:L$23)) | T19: =(M19*'Fund Ranking Criteria'!$D$9)+('Fund Ranking_Equity'!N19*'Fund Ranking Criteria'!$D$10)+('Fund Ranking_Equity'!O19*'Fund Ranking Criteria'!$D$11)+('Fund Ranking_Equity'!P19*'Fund Ranking Criteria'!$D$16)+('Fund Ranking_Equity'!Q19*'Fund Ranking Criteria'!$D$12)+('Fund Ranking_Equity'!R19*'Fund Ranking Criteria'!$D$14)+('Fund Ranking_Equity'!S19*'Fund Ranking Criteria'!$D$15)
B20: ICICI Prudential Large & Mid Cap Fund - Growth | C20: =RANK(T20,$T$17:$T$23,0) | D20: =B20 | E20: 2.4975 | F20: 14.5969 | G20: 15.6854 | H20: 14.3648 | I20: 0.066796684 | J20: 0.23923386 | K20: 0.84189184 | L20: 12.312303 | M20: =(F20-MIN(F$17:F$23))/(MAX(F$17:F$23)-MIN(F$17:F$23)) | N20: =(G20-MIN(G$17:G$23))/(MAX(G$17:G$23)-MIN(G$17:G$23)) | O20: =(H20-MIN(H$17:H$23))/(MAX(H$17:H$23)-MIN(H$17:H$23)) | P20: =(I20-MIN(I$17:I$23))/(MAX(I$17:I$23)-MIN(I$17:I$23)) | Q20: =(J20-MIN(J$17:J$23))/(MAX(J$17:J$23)-MIN(J$17:J$23)) | R20: =(MAX(K$17:K$23)-K20)/(MAX(K$17:K$23)-MIN(K$17:K$23)) | S20: =(MAX(L$17:L$23)-L20)/(MAX(L$17:L$23)-MIN(L$17:L$23)) | T20: =(M20*'Fund Ranking Criteria'!$D$9)+('Fund Ranking_Equity'!N20*'Fund Ranking Criteria'!$D$10)+('Fund Ranking_Equity'!O20*'Fund Ranking Criteria'!$D$11)+('Fund Ranking_Equity'!P20*'Fund Ranking Criteria'!$D$16)+('Fund Ranking_Equity'!Q20*'Fund Ranking Criteria'!$D$12)+('Fund Ranking_Equity'!R20*'Fund Ranking Criteria'!$D$14)+('Fund Ranking_Equity'!S20*'Fund Ranking Criteria'!$D$15)
B21: Nippon India Vision Large & Mid Cap Fund - Reg - Growth | C21: =RANK(T21,$T$17:$T$23,0) | D21: =B21 | E21: 0.4644 | F21: 13.3769 | G21: 12.5374 | H21: 12.1254 | I21: 0.058815614 | J21: 0.13172748 | K21: 0.9657727 | L21: 13.614211 | M21: =(F21-MIN(F$17:F$23))/(MAX(F$17:F$23)-MIN(F$17:F$23)) | N21: =(G21-MIN(G$17:G$23))/(MAX(G$17:G$23)-MIN(G$17:G$23)) | O21: =(H21-MIN(H$17:H$23))/(MAX(H$17:H$23)-MIN(H$17:H$23)) | P21: =(I21-MIN(I$17:I$23))/(MAX(I$17:I$23)-MIN(I$17:I$23)) | Q21: =(J21-MIN(J$17:J$23))/(MAX(J$17:J$23)-MIN(J$17:J$23)) | R21: =(MAX(K$17:K$23)-K21)/(MAX(K$17:K$23)-MIN(K$17:K$23)) | S21: =(MAX(L$17:L$23)-L21)/(MAX(L$17:L$23)-MIN(L$17:L$23)) | T21: =(M21*'Fund Ranking Criteria'!$D$9)+('Fund Ranking_Equity'!N21*'Fund Ranking Criteria'!$D$10)+('Fund Ranking_Equity'!O21*'Fund Ranking Criteria'!$D$11)+('Fund Ranking_Equity'!P21*'Fund Ranking Criteria'!$D$16)+('Fund Ranking_Equity'!Q21*'Fund Ranking Criteria'!$D$12)+('Fund Ranking_Equity'!R21*'Fund Ranking Criteria'!$D$14)+('Fund Ranking_Equity'!S21*'Fund Ranking Criteria'!$D$15)
B22: Aditya Birla Sun Life Large & Mid Cap Fund - Growth | C22: =RANK(T22,$T$17:$T$23,0) | D22: =B22 | E22: 5.6368 | F22: 10.2099 | G22: 7.154 | H22: 10.3163 | I22: 0.040254364 | J22: -0.12065563 | K22: 0.98947516 | L22: 14.029882 | M22: =(F22-MIN(F$17:F$23))/(MAX(F$17:F$23)-MIN(F$17:F$23)) | N22: =(G22-MIN(G$17:G$23))/(MAX(G$17:G$23)-MIN(G$17:G$23)) | O22: =(H22-MIN(H$17:H$23))/(MAX(H$17:H$23)-MIN(H$17:H$23)) | P22: =(I22-MIN(I$17:I$23))/(MAX(I$17:I$23)-MIN(I$17:I$23)) | Q22: =(J22-MIN(J$17:J$23))/(MAX(J$17:J$23)-MIN(J$17:J$23)) | R22: =(MAX(K$17:K$23)-K22)/(MAX(K$17:K$23)-MIN(K$17:K$23)) | S22: =(MAX(L$17:L$23)-L22)/(MAX(L$17:L$23)-MIN(L$17:L$23)) | T22: =(M22*'Fund Ranking Criteria'!$D$9)+('Fund Ranking_Equity'!N22*'Fund Ranking Criteria'!$D$10)+('Fund Ranking_Equity'!O22*'Fund Ranking Criteria'!$D$11)+('Fund Ranking_Equity'!P22*'Fund Ranking Criteria'!$D$16)+('Fund Ranking_Equity'!Q22*'Fund Ranking Criteria'!$D$12)+('Fund Ranking_Equity'!R22*'Fund Ranking Criteria'!$D$14)+('Fund Ranking_Equity'!S22*'Fund Ranking Criteria'!$D$15)
B23: UTI Large & Mid Cap Fund - Growth | C23: =RANK(T23,$T$17:$T$23,0) | D23: =B23 | E23: 1.9888 | F23: 13.635 | G23: 13.2483 | H23: 13.1218 | I23: 0.058672696 | J23: 0.12686859 | K23: 0.94269646 | L23: 13.292113 | M23: =(F23-MIN(F$17:F$23))/(MAX(F$17:F$23)-MIN(F$17:F$23)) | N23: =(G23-MIN(G$17:G$23))/(MAX(G$17:G$23)-MIN(G$17:G$23)) | O23: =(H23-MIN(H$17:H$23))/(MAX(H$17:H$23)-MIN(H$17:H$23)) | P23: =(I23-MIN(I$17:I$23))/(MAX(I$17:I$23)-MIN(I$17:I$23)) | Q23: =(J23-MIN(J$17:J$23))/(MAX(J$17:J$23)-MIN(J$17:J$23)) | R23: =(MAX(K$17:K$23)-K23)/(MAX(K$17:K$23)-MIN(K$17:K$23)) | S23: =(MAX(L$17:L$23)-L23)/(MAX(L$17:L$23)-MIN(L$17:L$23)) | T23: =(M23*'Fund Ranking Criteria'!$D$9)+('Fund Ranking_Equity'!N23*'Fund Ranking Criteria'!$D$10)+('Fund Ranking_Equity'!O23*'Fund Ranking Criteria'!$D$11)+('Fund Ranking_Equity'!P23*'Fund Ranking Criteria'!$D$16)+('Fund Ranking_Equity'!Q23*'Fund Ranking Criteria'!$D$12)+('Fund Ranking_Equity'!R23*'Fund Ranking Criteria'!$D$14)+('Fund Ranking_Equity'!S23*'Fund Ranking Criteria'!$D$15)
B25: Equity Mid Cap
E26: Actuals | M26: Normalized
B27: Funds | C27: Rank | E27: 1 Yr Ret (%) | F27: 3 Yr Ret (%) | G27: 5 Yr Ret (%) | H27: 10 Yr Ret (%) | I27: Sharpe | J27: Alpha | K27: Beta | L27: SD | M27: =F27 | N27: =G27 | O27: =H27 | P27: Sharpe | Q27: Alpha | R27: Beta | S27: SD
B28: HDFC Mid Cap Fund - Growth | C28: =RANK(T28,$T$28:$T$34,0) | D28: =B28 | E28: 7.0827 | F28: 16.1748 | G28: 18.3884 | H28: 16.3787 | I28: 0.074549824 | J28: 0.18668473 | K28: 0.84390926 | L28: 14.020148 | M28: =(F28-MIN(F$28:F$34))/(MAX(F$28:F$34)-MIN(F$28:F$34)) | N28: =(G28-MIN(G$28:G$34))/(MAX(G$28:G$34)-MIN(G$28:G$34)) | O28: =(H28-MIN(H$28:H$34))/(MAX(H$28:H$34)-MIN(H$28:H$34)) | P28: =(I28-MIN(I$28:I$34))/(MAX(I$28:I$34)-MIN(I$28:I$34)) | Q28: =(J28-MIN(J$28:J$34))/(MAX(J$28:J$34)-MIN(J$28:J$34)) | R28: =(MAX(K$28:K$34)-K28)/(MAX(K$28:K$34)-MIN(K$28:K$34)) | S28: =(MAX(L$28:L$34)-L28)/(MAX(L$28:L$34)-MIN(L$28:L$34)) | T28: =(M28*'Fund Ranking Criteria'!$F$9)+('Fund Ranking_Equity'!N28*'Fund Ranking Criteria'!$F$10)+('Fund Ranking_Equity'!O28*'Fund Ranking Criteria'!$F$11)+('Fund Ranking_Equity'!P28*'Fund Ranking Criteria'!$F$16)+('Fund Ranking_Equity'!Q28*'Fund Ranking Criteria'!$F$12)+('Fund Ranking_Equity'!R28*'Fund Ranking Criteria'!$F$14)+('Fund Ranking_Equity'!S28*'Fund Ranking Criteria'!$F$15)
B29: Kotak Midcap Fund - Reg - Growth | C29: =RANK(T29,$T$28:$T$34,0) | D29: =B29 | E29: 7.8792 | F29: 17.491 | G29: 15.9466 | H29: 16.7558 | I29: 0.069810634 | J29: -0.082783429 | K29: 0.95630962 | L29: 16.167653 | M29: =(F29-MIN(F$28:F$34))/(MAX(F$28:F$34)-MIN(F$28:F$34)) | N29: =(G29-MIN(G$28:G$34))/(MAX(G$28:G$34)-MIN(G$28:G$34)) | O29: =(H29-MIN(H$28:H$34))/(MAX(H$28:H$34)-MIN(H$28:H$34)) | P29: =(I29-MIN(I$28:I$34))/(MAX(I$28:I$34)-MIN(I$28:I$34)) | Q29: =(J29-MIN(J$28:J$34))/(MAX(J$28:J$34)-MIN(J$28:J$34)) | R29: =(MAX(K$28:K$34)-K29)/(MAX(K$28:K$34)-MIN(K$28:K$34)) | S29: =(MAX(L$28:L$34)-L29)/(MAX(L$28:L$34)-MIN(L$28:L$34)) | T29: =(M29*'Fund Ranking Criteria'!$F$9)+('Fund Ranking_Equity'!N29*'Fund Ranking Criteria'!$F$10)+('Fund Ranking_Equity'!O29*'Fund Ranking Criteria'!$F$11)+('Fund Ranking_Equity'!P29*'Fund Ranking Criteria'!$F$16)+('Fund Ranking_Equity'!Q29*'Fund Ranking Criteria'!$F$12)+('Fund Ranking_Equity'!R29*'Fund Ranking Criteria'!$F$14)+('Fund Ranking_Equity'!S29*'Fund Ranking Criteria'!$F$15)
B30: Nippon India Growth Mid Cap Fund - Reg - Growth | C30: =RANK(T30,$T$28:$T$34,0) | D30: =B30 | E30: 7.6062 | F30: 16.79 | G30: 17.3673 | H30: 17.3071 | I30: 0.072448607 | J30: 0.16672352 | K30: 0.94884865 | L30: 15.624786 | M30: =(F30-MIN(F$28:F$34))/(MAX(F$28:F$34)-MIN(F$28:F$34)) | N30: =(G30-MIN(G$28:G$34))/(MAX(G$28:G$34)-MIN(G$28:G$34)) | O30: =(H30-MIN(H$28:H$34))/(MAX(H$28:H$34)-MIN(H$28:H$34)) | P30: =(I30-MIN(I$28:I$34))/(MAX(I$28:I$34)-MIN(I$28:I$34)) | Q30: =(J30-MIN(J$28:J$34))/(MAX(J$28:J$34)-MIN(J$28:J$34)) | R30: =(MAX(K$28:K$34)-K30)/(MAX(K$28:K$34)-MIN(K$28:K$34)) | S30: =(MAX(L$28:L$34)-L30)/(MAX(L$28:L$34)-MIN(L$28:L$34)) | T30: =(M30*'Fund Ranking Criteria'!$F$9)+('Fund Ranking_Equity'!N30*'Fund Ranking Criteria'!$F$10)+('Fund Ranking_Equity'!O30*'Fund Ranking Criteria'!$F$11)+('Fund Ranking_Equity'!P30*'Fund Ranking Criteria'!$F$16)+('Fund Ranking_Equity'!Q30*'Fund Ranking Criteria'!$F$12)+('Fund Ranking_Equity'!R30*'Fund Ranking Criteria'!$F$14)+('Fund Ranking_Equity'!S30*'Fund Ranking Criteria'!$F$15)
B31: SBI Midcap Fund - Growth | C31: =RANK(T31,$T$28:$T$34,0) | D31: =B31 | E31: 4.6854 | F31: 9.4698 | G31: 12.7899 | H31: 13.0151 | I31: 0.040694755 | J31: -0.25798466 | K31: 0.79923107 | L31: 13.640056 | M31: =(F31-MIN(F$28:F$34))/(MAX(F$28:F$34)-MIN(F$28:F$34)) | N31: =(G31-MIN(G$28:G$34))/(MAX(G$28:G$34)-MIN(G$28:G$34)) | O31: =(H31-MIN(H$28:H$34))/(MAX(H$28:H$34)-MIN(H$28:H$34)) | P31: =(I31-MIN(I$28:I$34))/(MAX(I$28:I$34)-MIN(I$28:I$34)) | Q31: =(J31-MIN(J$28:J$34))/(MAX(J$28:J$34)-MIN(J$28:J$34)) | R31: =(MAX(K$28:K$34)-K31)/(MAX(K$28:K$34)-MIN(K$28:K$34)) | S31: =(MAX(L$28:L$34)-L31)/(MAX(L$28:L$34)-MIN(L$28:L$34)) | T31: =(M31*'Fund Ranking Criteria'!$F$9)+('Fund Ranking_Equity'!N31*'Fund Ranking Criteria'!$F$10)+('Fund Ranking_Equity'!O31*'Fund Ranking Criteria'!$F$11)+('Fund Ranking_Equity'!P31*'Fund Ranking Criteria'!$F$16)+('Fund Ranking_Equity'!Q31*'Fund Ranking Criteria'!$F$12)+('Fund Ranking_Equity'!R31*'Fund Ranking Criteria'!$F$14)+('Fund Ranking_Equity'!S31*'Fund Ranking Criteria'!$F$15)
B32: UTI Mid Cap Fund - Growth | C32: =RANK(T32,$T$28:$T$34,0) | D32: =B32 | E32: 4.1276 | F32: 10.7305 | G32: 11.2781 | H32: 13.0951 | I32: 0.040930162 | J32: -0.31134377 | K32: 0.93039444 | L32: 15.517971 | M32: =(F32-MIN(F$28:F$34))/(MAX(F$28:F$34)-MIN(F$28:F$34)) | N32: =(G32-MIN(G$28:G$34))/(MAX(G$28:G$34)-MIN(G$28:G$34)) | O32: =(H32-MIN(H$28:H$34))/(MAX(H$28:H$34)-MIN(H$28:H$34)) | P32: =(I32-MIN(I$28:I$34))/(MAX(I$28:I$34)-MIN(I$28:I$34)) | Q32: =(J32-MIN(J$28:J$34))/(MAX(J$28:J$34)-MIN(J$28:J$34)) | R32: =(MAX(K$28:K$34)-K32)/(MAX(K$28:K$34)-MIN(K$28:K$34)) | S32: =(MAX(L$28:L$34)-L32)/(MAX(L$28:L$34)-MIN(L$28:L$34)) | T32: =(M32*'Fund Ranking Criteria'!$F$9)+('Fund Ranking_Equity'!N32*'Fund Ranking Criteria'!$F$10)+('Fund Ranking_Equity'!O32*'Fund Ranking Criteria'!$F$11)+('Fund Ranking_Equity'!P32*'Fund Ranking Criteria'!$F$16)+('Fund Ranking_Equity'!Q32*'Fund Ranking Criteria'!$F$12)+('Fund Ranking_Equity'!R32*'Fund Ranking Criteria'!$F$14)+('Fund Ranking_Equity'!S32*'Fund Ranking Criteria'!$F$15)
B33: ICICI Prudential MidCap Fund - Growth | C33: =RANK(T33,$T$28:$T$34,0) | D33: =B33 | E33: 18.8078 | F33: 23.2072 | G33: 18.0556 | H33: 16.7025 | I33: 0.081017605 | J33: 0.23982825 | K33: 1.0063932 | L33: 18.357031 | M33: =(F33-MIN(F$28:F$34))/(MAX(F$28:F$34)-MIN(F$28:F$34)) | N33: =(G33-MIN(G$28:G$34))/(MAX(G$28:G$34)-MIN(G$28:G$34)) | O33: =(H33-MIN(H$28:H$34))/(MAX(H$28:H$34)-MIN(H$28:H$34)) | P33: =(I33-MIN(I$28:I$34))/(MAX(I$28:I$34)-MIN(I$28:I$34)) | Q33: =(J33-MIN(J$28:J$34))/(MAX(J$28:J$34)-MIN(J$28:J$34)) | R33: =(MAX(K$28:K$34)-K33)/(MAX(K$28:K$34)-MIN(K$28:K$34)) | S33: =(MAX(L$28:L$34)-L33)/(MAX(L$28:L$34)-MIN(L$28:L$34)) | T33: =(M33*'Fund Ranking Criteria'!$F$9)+('Fund Ranking_Equity'!N33*'Fund Ranking Criteria'!$F$10)+('Fund Ranking_Equity'!O33*'Fund Ranking Criteria'!$F$11)+('Fund Ranking_Equity'!P33*'Fund Ranking Criteria'!$F$16)+('Fund Ranking_Equity'!Q33*'Fund Ranking Criteria'!$F$12)+('Fund Ranking_Equity'!R33*'Fund Ranking Criteria'!$F$14)+('Fund Ranking_Equity'!S33*'Fund Ranking Criteria'!$F$15)
B34: Aditya Birla Sun Life Mid Cap Fund - Plan A - Growth | C34: =RANK(T34,$T$28:$T$34,0) | D34: =B34 | E34: 7.4405 | F34: 13.9556 | G34: 13.402 | H34: 12.7065 | I34: 0.059117659 | J34: -0.031066366 | K34: 0.93009716 | L34: 15.479775 | M34: =(F34-MIN(F$28:F$34))/(MAX(F$28:F$34)-MIN(F$28:F$34)) | N34: =(G34-MIN(G$28:G$34))/(MAX(G$28:G$34)-MIN(G$28:G$34)) | O34: =(H34-MIN(H$28:H$34))/(MAX(H$28:H$34)-MIN(H$28:H$34)) | P34: =(I34-MIN(I$28:I$34))/(MAX(I$28:I$34)-MIN(I$28:I$34)) | Q34: =(J34-MIN(J$28:J$34))/(MAX(J$28:J$34)-MIN(J$28:J$34)) | R34: =(MAX(K$28:K$34)-K34)/(MAX(K$28:K$34)-MIN(K$28:K$34)) | S34: =(MAX(L$28:L$34)-L34)/(MAX(L$28:L$34)-MIN(L$28:L$34)) | T34: =(M34*'Fund Ranking Criteria'!$F$9)+('Fund Ranking_Equity'!N34*'Fund Ranking Criteria'!$F$10)+('Fund Ranking_Equity'!O34*'Fund Ranking Criteria'!$F$11)+('Fund Ranking_Equity'!P34*'Fund Ranking Criteria'!$F$16)+('Fund Ranking_Equity'!Q34*'Fund Ranking Criteria'!$F$12)+('Fund Ranking_Equity'!R34*'Fund Ranking Criteria'!$F$14)+('Fund Ranking_Equity'!S34*'Fund Ranking Criteria'!$F$15)
B36: Equity Small Cap
E37: Actuals | M37: Normalized
B38: Funds | C38: Rank | E38: 1 Yr Ret (%) | F38: 3 Yr Ret (%) | G38: 5 Yr Ret (%) | H38: 10 Yr Ret (%) | I38: Sharpe | J38: Alpha | K38: Beta | L38: SD | M38: =F38 | N38: =G38 | O38: =H38 | P38: Sharpe | Q38: Alpha | R38: Beta | S38: SD
B39: Nippon India Small Cap Fund - Reg - Growth | C39: =RANK(T39,$T$39:$T$45,0) | D39: =B39 | E39: 9.2309 | F39: 13.8546 | G39: 18.2561 | H39: 20.0437 | I39: 0.055582047 | J39: 0.033954954 | K39: 0.83774233 | L39: 16.899822 | M39: =(F39-MIN(F$39:F$45))/(MAX(F$39:F$45)-MIN(F$39:F$45)) | N39: =(G39-MIN(G$39:G$45))/(MAX(G$39:G$45)-MIN(G$39:G$45)) | O39: =(H39-MIN(H$39:H$45))/(MAX(H$39:H$45)-MIN(H$39:H$45)) | P39: =(I39-MIN(I$39:I$45))/(MAX(I$39:I$45)-MIN(I$39:I$45)) | Q39: =(J39-MIN(J$39:J$45))/(MAX(J$39:J$45)-MIN(J$39:J$45)) | R39: =(MAX(K$39:K$45)-K39)/(MAX(K$39:K$45)-MIN(K$39:K$45)) | S39: =(MAX(L$39:L$45)-L39)/(MAX(L$39:L$45)-MIN(L$39:L$45)) | T39: =(M39*'Fund Ranking Criteria'!$G$9)+('Fund Ranking_Equity'!N39*'Fund Ranking Criteria'!$G$10)+('Fund Ranking_Equity'!O39*'Fund Ranking Criteria'!$G$11)+('Fund Ranking_Equity'!P39*'Fund Ranking Criteria'!$G$16)+('Fund Ranking_Equity'!Q39*'Fund Ranking Criteria'!$G$12)+('Fund Ranking_Equity'!R39*'Fund Ranking Criteria'!$G$14)+('Fund Ranking_Equity'!S39*'Fund Ranking Criteria'!$G$15)
